<?xml version="1.0" ?>
<!-- =================================================================================== -->
<!-- |    This document was autogenerated by xacro from /home/joep/foxy_ws/install/ackermann_simulation/share/ackermann_simulation/urdf/ackermann_model.urdf.xacro | -->
<!-- |    EDITING THIS FILE BY HAND IS NOT RECOMMENDED                                 | -->
<!-- =================================================================================== -->
<robot name="ackermann_robot">
  <!-- Steering -->
  <link name="base_footprint"/>
  <joint name="base_joint" type="fixed">
    <parent link="base_footprint"/>
    <child link="base_link"/>
    <origin rpy="0 0 0" xyz="0.0 0.0 0.075"/>
  </joint>
  <link name="base_link">
    <visual>
      <origin rpy="0 0 0" xyz="-0.785 -0.747 -0.15"/>
      <geometry>
        <mesh filename="model://ackermann_model/meshes/base_link.stl" scale="0.01 0.01 0.01"/>
      </geometry>
      <material name="red">
        <color rgba="0.8 0.0 0.0 1.0"/>
      </material>
    </visual>
    <collision>
      <origin rpy="0 0 0" xyz="-0.035 0 0.02"/>
      <geometry>
        <box size="1 0.38 0.24"/>
      </geometry>
    </collision>
    <inertial>
      <mass value="15.0"/>
      <origin xyz="0.0 0 0.0"/>
      <inertia ixx="2.3" ixy="0.0" ixz="0.0" iyy="1.0" iyz="0.0" izz="1.5"/>
    </inertial>
  </link>
  <gazebo reference="base_link">
    <selfCollide>false</selfCollide>
    <material value="Gazebo/Red"/>
    <turnGravityOff>false</turnGravityOff>
  </gazebo>
  <link name="steering_wheel_front_left">
    <inertial>
      <mass value="1.0"/>
      <origin xyz="0.0 0 0.0"/>
      <inertia ixx="0.001" ixy="0.0" ixz="0.0" iyy="0.001" iyz="0.0" izz="0.001"/>
    </inertial>
  </link>
  <gazebo reference="steering_wheel_front_left">
    <material>Gazebo/White</material>
    <turnGravityOff>false</turnGravityOff>
  </gazebo>
  <joint name="steering_wheel_front_left_joint" type="revolute">
    <parent link="base_link"/>
    <child link="steering_wheel_front_left"/>
    <origin rpy="0 0 0" xyz="0.308 0.175 -0.075"/>
    <axis xyz="0 0 1"/>
    <limit effort="20.0" lower="-0.7" upper="0.7" velocity="5.0"/>
    <dynamics damping="0.4" friction="0.5"/>
  </joint>
  <link name="wheel_front_left">
    <visual>
      <origin rpy="-1.570796327 0  0" xyz="0 -0.023 0"/>
      <geometry>
        <mesh filename="model://ackermann_model/meshes/wheel.stl" scale="0.0055 0.0055 0.0055"/>
      </geometry>
      <material name="black"/>
    </visual>
    <collision>
      <origin rpy="1.570796327 0 0" xyz="0 0 0"/>
      <geometry>
        <cylinder length="0.04" radius="0.075"/>
      </geometry>
    </collision>
    <inertial>
      <mass value="1.5"/>
      <origin xyz="0 0 0"/>
      <inertia ixx="0.002309375" ixy="0" ixz="0" iyy="0.002309375" iyz="0" izz="0.004218749999999999"/>
    </inertial>
  </link>
  <gazebo reference="wheel_front_left">
    <material>Gazebo/Black</material>
    <turnGravityOff>false</turnGravityOff>
  </gazebo>
  <joint name="wheel_front_left_joint" type="revolute">
    <parent link="steering_wheel_front_left"/>
    <child link="wheel_front_left"/>
    <origin rpy="0 0 0" xyz="0.0 0.0 0.0"/>
    <axis xyz="0 1 0"/>
    <limit effort="20.0" lower="-1e+16" upper="1e+16" velocity="5.0"/>
    <dynamics damping="0.4" friction="0.5"/>
  </joint>
  <link name="steering_wheel_front_right">
    <inertial>
      <mass value="1.0"/>
      <origin xyz="0.0 0 0.0"/>
      <inertia ixx="0.001" ixy="0.0" ixz="0.0" iyy="0.001" iyz="0.0" izz="0.001"/>
    </inertial>
  </link>
  <gazebo reference="steering_wheel_front_right">
    <material>Gazebo/White</material>
    <turnGravityOff>false</turnGravityOff>
  </gazebo>
  <joint name="steering_wheel_front_right_joint" type="revolute">
    <parent link="base_link"/>
    <child link="steering_wheel_front_right"/>
    <origin rpy="0 0 0" xyz="0.308 -0.175 -0.075"/>
    <axis xyz="0 0 1"/>
    <limit effort="20.0" lower="-0.7" upper="0.7" velocity="5.0"/>
    <dynamics damping="0.4" friction="0.5"/>
  </joint>
  <link name="wheel_front_right">
    <visual>
      <origin rpy="1.570796327 0  0" xyz="0 0.025 0"/>
      <geometry>
        <mesh filename="model://ackermann_model/meshes/wheel.stl" scale="0.0055 0.0055 0.0055"/>
      </geometry>
      <material name="black"/>
    </visual>
    <collision>
      <origin rpy="1.570796327 0 0" xyz="0 0 0"/>
      <geometry>
        <cylinder length="0.04" radius="0.075"/>
      </geometry>
    </collision>
    <inertial>
      <mass value="1.5"/>
      <origin xyz="0 0 0"/>
      <inertia ixx="0.002309375" ixy="0" ixz="0" iyy="0.002309375" iyz="0" izz="0.004218749999999999"/>
    </inertial>
  </link>
  <gazebo reference="wheel_front_right">
    <material>Gazebo/Black</material>
    <turnGravityOff>false</turnGravityOff>
  </gazebo>
  <joint name="wheel_front_right_joint" type="revolute">
    <parent link="steering_wheel_front_right"/>
    <child link="wheel_front_right"/>
    <origin rpy="0 0 0" xyz="0.0 0.0 0.0"/>
    <axis xyz="0 1 0"/>
    <limit effort="20.0" lower="-1e+16" upper="1e+16" velocity="5.0"/>
    <dynamics damping="0.4" friction="0.5"/>
  </joint>
  <link name="wheel_back_left">
    <visual>
      <origin rpy="-1.570796327 0  0" xyz="0 -0.023 0"/>
      <geometry>
        <mesh filename="model://ackermann_model/meshes/wheel.stl" scale="0.0055 0.0055 0.0055"/>
      </geometry>
      <material name="black"/>
    </visual>
    <collision>
      <origin rpy="1.570796327 0 0" xyz="0 0 0"/>
      <geometry>
        <cylinder length="0.04" radius="0.075"/>
      </geometry>
    </collision>
    <inertial>
      <mass value="1.5"/>
      <origin xyz="0 0 0"/>
      <inertia ixx="0.002309375" ixy="0" ixz="0" iyy="0.002309375" iyz="0" izz="0.004218749999999999"/>
    </inertial>
  </link>
  <gazebo reference="wheel_back_left">
    <material>Gazebo/Black</material>
    <turnGravityOff>false</turnGravityOff>
  </gazebo>
  <joint name="wheel_back_left_joint" type="revolute">
    <parent link="base_link"/>
    <child link="wheel_back_left"/>
    <origin rpy="0 0 0" xyz="-0.308 0.175 -0.075"/>
    <axis xyz="0 1 0"/>
    <limit effort="20.0" lower="-1e+16" upper="1e+16" velocity="5.0"/>
    <dynamics damping="0.4" friction="0.5"/>
  </joint>
  <link name="wheel_back_right">
    <visual>
      <origin rpy="1.570796327 0  0" xyz="0 0.025 0"/>
      <geometry>
        <mesh filename="model://ackermann_model/meshes/wheel.stl" scale="0.0055 0.0055 0.0055"/>
      </geometry>
      <material name="black"/>
    </visual>
    <collision>
      <origin rpy="1.570796327 0 0" xyz="0 0 0"/>
      <geometry>
        <cylinder length="0.04" radius="0.075"/>
      </geometry>
    </collision>
    <inertial>
      <mass value="1.5"/>
      <origin xyz="0 0 0"/>
      <inertia ixx="0.002309375" ixy="0" ixz="0" iyy="0.002309375" iyz="0" izz="0.004218749999999999"/>
    </inertial>
  </link>
  <gazebo reference="wheel_back_right">
    <material>Gazebo/Black</material>
    <turnGravityOff>false</turnGravityOff>
  </gazebo>
  <joint name="wheel_back_right_joint" type="revolute">
    <parent link="base_link"/>
    <child link="wheel_back_right"/>
    <origin rpy="0 0 0" xyz="-0.308 -0.175 -0.075"/>
    <axis xyz="0 1 0"/>
    <limit effort="20.0" lower="-1e+16" upper="1e+16" velocity="5.0"/>
    <dynamics damping="0.4" friction="0.5"/>
  </joint>
  <gazebo>
    <plugin filename="libgazebo_ros_joint_state_publisher.so" name="joint_state_publisher">
      <ros>
        <remapping>~/out:=joint_states</remapping>
      </ros>
      <update_rate>30</update_rate>
      <joint_name>wheel_front_left_joint</joint_name>
      <joint_name>wheel_front_right_joint</joint_name>
      <joint_name>wheel_back_left_joint</joint_name>
      <joint_name>wheel_back_right_joint</joint_name>
      <joint_name>steering_wheel_front_left_joint</joint_name>
      <joint_name>steering_wheel_front_right_joint</joint_name>
    </plugin>
    <plugin filename="libgazebo_ros_ackermann_drive.so" name="gazebo_ros_ackermann_drive">
      <update_rate>100.0</update_rate>
      <!-- wheels -->
      <front_left_joint>wheel_front_left_joint</front_left_joint>
      <front_right_joint>wheel_front_right_joint</front_right_joint>
      <rear_left_joint>wheel_back_left_joint</rear_left_joint>
      <rear_right_joint>wheel_back_right_joint</rear_right_joint>
      <left_steering_joint>steering_wheel_front_left_joint</left_steering_joint>
      <right_steering_joint>steering_wheel_front_right_joint</right_steering_joint>
      <!-- Max absolute steer angle for tyre in radians-->
      <!-- Any cmd_vel angular z greater than this would be capped -->
      <max_steer>0.7</max_steer>
      <max_speed>20</max_speed>
      <!-- PID tuning -->
      <left_steering_pid_gain>75 0 1</left_steering_pid_gain>
      <left_steering_i_range>0 0</left_steering_i_range>
      <right_steering_pid_gain>75 0 1</right_steering_pid_gain>
      <right_steering_i_range>0 0</right_steering_i_range>
      <linear_velocity_pid_gain>50 0 1</linear_velocity_pid_gain>
      <linear_velocity_i_range>0 0</linear_velocity_i_range>
      <!-- output -->
      <publish_odom>true</publish_odom>
      <publish_odom_tf>true</publish_odom_tf>
      <publish_wheel_tf>true</publish_wheel_tf>
      <publish_distance>true</publish_distance>
      <odometry_frame>odom</odometry_frame>
      <robot_base_frame>base_footprint</robot_base_frame>
    </plugin>
  </gazebo>
  <joint name="lidar_scan_joint" type="fixed">
    <parent link="base_link"/>
    <child link="lidar_scan"/>
    <origin rpy="0 0 0" xyz="-0.06 0.0 0.165"/>
  </joint>
  <link name="lidar_scan">
    <visual>
      <origin rpy="0 0 0" xyz="0 0 0.0"/>
      <geometry>
        <mesh filename="model://ackermann_model/meshes/lds.stl" scale="0.001 0.001 0.001"/>
      </geometry>
      <material name="grey">
        <color rgba="0.3 0.3 0.3 1.0"/>
      </material>
    </visual>
    <collision>
      <origin rpy="0 0 0" xyz="0.015 0 -0.0065"/>
      <geometry>
        <cylinder length="0.0315" radius="0.055"/>
      </geometry>
    </collision>
    <inertial>
      <mass value="0.114"/>
      <origin xyz="0 0 0"/>
      <inertia ixx="0.001" ixy="0.0" ixz="0.0" iyy="0.001" iyz="0.0" izz="0.001"/>
    </inertial>
  </link>
  <gazebo reference="lidar_scan">
    <material value="Gazebo/Grey"/>
    <sensor name="hls_lfcd_lds" type="ray">
      <always_on>true</always_on>
      <visualize>false</visualize>
      <pose>-0.032 0 0.171 0 0 0</pose>
      <update_rate>5</update_rate>
      <ray>
        <scan>
          <horizontal>
            <samples>360</samples>
            <resolution>1.000000</resolution>
            <min_angle>0.000000</min_angle>
            <max_angle>6.280000</max_angle>
          </horizontal>
        </scan>
        <range>
          <min>0.50000</min>
          <max>5.0</max>
          <resolution>0.015000</resolution>
        </range>
        <noise>
          <type>gaussian</type>
          <mean>0.0</mean>
          <stddev>0.01</stddev>
        </noise>
      </ray>
      <plugin filename="libgazebo_ros_ray_sensor.so" name="ackermann_scan">
        <ros>
          <remapping>~/out:=scan</remapping>
        </ros>
        <output_type>sensor_msgs/LaserScan</output_type>
        <frame_name>lidar_scan</frame_name>
      </plugin>
    </sensor>
  </gazebo>
</robot>
